Workbook

Sheet PASO A PASO
G3: PASO A PASO EN LA OCURRENCIA DE UN INCIDENTE/ACCIDENTE LABORAL | Y3: Código: | Z3: RE-20-1
Y4: Versión: | Z4: 2
Y5: Fecha: | Z5: 45691
B7: Pasos a seguir cuando ocurre un ACCIDENTE LABORAL. | N7: NOTA: EN CASO ACCIDENTE TRAYECTO CUMPLIR ITEMS 1, 2 Y 3
A9: ACTIVIDAD | L9: RESPONSABLE | Q9: PLAZO | Y9: FORMULARIO/DOCUMENTO DE ENTREGA | Z9: INFORME DERIVADO A:
A10: 1 | B10: INFORMA R Y RECOPILAR DATOS PARA INVESTIGACION PRELIMINAR DE ACCIDENTE EN SU TURNO | L10: JEFE DE TERRENO O SUPERVISOR | Q10: INMEDIATO | Y10: CORREO O LLAMADO CELULAR | Z10: ADMINISTRADOR DE CONTRATO PREVENCION DE RIESGO
A14: 2 | B14: INFORMAR EL INCIDENTE /ACCIDENTE | L14: PREVENCION DE RIESGOS | Q14: INMEDIATO | Y14: CORREO O LLAMADO CELULAR | Z14: JEFE DPTO. PREVENCION DE RIESGOS
A16: 3 | B16: REALIZAR Y ENVIAR INVESTIGACION PRELIMINAR DE ACCIDENTE. | L16: JEFE DE TERRENO o SUPERVISOR PREVENCIÓN DE RIESGOS (Envia el correo) | Q16: CONSOLIDAR ANTECEDENTES Y REALIZAR INFORME: INMEDIATA 3 HORAS DE OCURRIDO EL ACCIDENTE E INCIDENTE | Y16: PRE-INV 01
Z17: GERENTE GENERAL
Z18: TODAS LAS SUBGERENCIAS
Z19: JEFE DPTO. PREVENCIÓN DE RIESGOS
Z20: ADMINISTRADOR DE CONTRATO
Z21: COMITÉ PARITARIO
Z22: TODOS LOS CORREOS DE PREVENCIÓN
Z23: DE RIESGOS
A25: 4 | B25: ENTREVISTA A TESTIGOS | L25: COMISIÓN INVESTIGACIÓN ACCIDENTES COMITÉ PARITARIO PREVENCION DE RIESGOS JEFE DE TERRENO O SUPERVISOR | Q25: 5 hrs DESPUES DE OCURRIDO EL ACCIDENTE E INCIDENTE | Y25: ENT- TESTIGOS | Z25: ADMINISTRADOR DE CONTRATO PREVENCION DE RIESGO COMITÉ PARITARIO
A27: 5 | B27: REALIZACIÓN DIAT | L27: ADMINISTRADOR DE CONTRATO (FIRMA) PREVENCION DE RIESGOS | Q27: MAXIMO 24 HORAS OCURRIDO EL ACCIDENTE E INCIDENTE
Z28: MUTUALIDAD
Y29: DIAT | Z29: GERENTE GENERAL
Z30: JEFE DPTO. PREVENCIÓN DE RIESGOS
A32: 6 | B32: ENTREVISTA AL ACCIDENTADO | L32: COMITÉ PARITARIO | Q32: DESDE EL MOMENTO DEL ENVÍO DEL INFORME PRE LIMINAR 24 HORAS. | Y32: ENT-CPHS
Z33: GERENTE GENERAL
B34: CONTAR CON LA INFORMACIÓN DIRECTA DEL ACCIDENTADO POR MEDIO DE ESTA HERRAMIENTA A REALIZAR EN FORMA PRESENCIAL O TELEFONICA, DEL PORQUE DE LA OCURRENCIA DEL ACCIDENTE. | Z34: TODAS LAS SUBGERENCIAS
Z35: JEFE DPTO. PREVECIÓN DE RIESGOS
Z36: ADMINISTRADOR DE CONTRATO
Z37: JEFE TERRENO
A38: 7 | B38: REALIZAR EVALUACIÓN Y VALIDACIÓN INFORME PRELIMINAR DE ACCIDENTE: | L38: COMISIÓN INVESTIGACIÓN ACCIDENTES COMITÉ PARITARIO | Y38: INVDEF.ACC INVESTIGACIÓN DEFINITIVA DE ACCIDENTES
Q39: 72 HORAS DE LA RECEPCIÓN DE INVESTIGACIÓN PRE LIMINAR | Z39: GERENTE GENERAL
B40: ESTABLECER MEDIDAS CORRECTIVAS TRANSITORIAS. | L40: ADMINISTRADOR DE CONTRATO/JEFE TERRENO | Z40: TODAS LAS SUBGERENCIAS
B41: ESTABLECER MEJORAS. | L41: PREVENCIÓN DE RIESGOS | Z41: JEFE DPTO. PREVENCION DE RIESGOS
B42: DEFINIR RESPONSABLES DE MEDIDAS CORRECTIVAS Y PLAZOS DE EJECUCIÓN. | L42: SUBGERENCIA DEL AREA
B43: GENERAR INFORME FINAL DE ACCIDENTE. | Z43: COMITÉ PARITARIO
L44: (Adm. De contrato envia el correo)
A45: 8 | Y45: BRIEFING DE SEGURIDAD, ALERTA DE PELIGRO. INF. DIFUSIÓN, REG.ASISTENCIA
B46: DIFUNDIR MEDIDAS CORRECTIVAS TRANSITORIAS/DEFINITIVAS Y MEJORAS A REALIZAR | L46: COMITÉ PARITARIO | Q46: 24 HORAS, DESPUÉS DE REUNION DE EVALUACIÓN Y VALIDACIÓN DE ACCIDENTE | Z46: GERENTE GENERAL
L47: ADMINISTRADOR DE CONTRATO/JEFE TERRENO | Z47: TODAS LAS SUBGERENCIAS
Z48: JEFE DPTO. PREVENCIÓN DE RIESGOS
L49: PREVENCION DE RIESGOS (registro asistencia y infmormativo de difusión ) | Z49: ADMINISTRADOR DE CONTRATO
L50: (todos difunden) | Z50: COMITÉ PARITARIO
A51: 9 | B51: REUNIÓN POST ACCIDENTES
...

Sheet INV.PRE.ACC
C3: #VALUE! | F3: INVESTIGACIÓN PRELIMINAR DE ACCIDENTES E INCIDENTES | T3: Código | V3: RE-20-02
T4: Versión | V4: 1
T5: Fecha: | V5: 45691
C7: NOMBRE JEFATURA A CARGO:
C8: FECHA INFORME:
C9: SUB GERENCIA:
C10: AREA/TALLER:
C12: IDENTIFICACIÓN DEL ACCIDENTADO/ PERSONAL INVOLUCRADO EN EL INCIDENTE
C14: 1.- | D14: NOMBRE:
C17: 2.- | D17: RUT:
C20: 3.- | D20: CARGO:
C23: 4.- | D23: LUGAR EXACTO DEL ACCIDENTE:
C26: CLASIFICACIÓN DEL ACCIDENTE/INCIDENTE.
C28: 5.- | D28: DESCRIPCIÓN DE LO OCURRIDO:
C34: 6.- | D34: PARTE DEL CUERPO LESIONADA. | N34: 8.- | O34: QUE ELEMENTO(S) PROVOCA LA LESIÓN
C37: DATOS
C39: 9.- | D39: FECHA DEL ACCIDENTE E INCIDENTE: | N39: 10.- | O39: HORA DEL ACCIDENTE E INCIDENTE:
C42: 11.- | D42: HORA DE INGRESO/SALIDA DE TURNO:
C44: I: | K44: S:
C48: 12.- | D48: OTROS ANTECEDENTES Y/O DETALLE DE INFORMACION ANEXA | P48: (LISTAS DESPLEGABLES EN CADA ITEM)
C51: PELIGRO (acto o fuente)
C52: Especificar Otros:
C54: TEMPERATURAS
C56: CLIMA
C58: SISTEMA DE TURNOS
C64: QUE DESVIACIONES A LOS PROCEDIMIENTOS, EN LOS EQUIPOS O EN EL ENTORNO SEGÚN SU EVALUACIÓN GENERARON LA OCURRENCIA DEL ACCIDENTE E INCIDENTE
C71: FOTOGRAFÍA
C94: QUE ACCIÓN CORRECTIVA PALEATIVA SE REALIZÓ INMEDIATAMENTE DESPUÉS DE OCURRIDO EL ACCIDENTE E INCIDENTE
C95: ACCIÓN | U95: RESPONSABLE
C101: QUE MEDIDA(S) CREE USTED QUE SE DEBERÍA(N) REALIZAR PARA LA NO REPETICIÓN DEL ACCIDENTE E INCIDENTE OCURRIDO.
C103: 1
C106: 2

Sheet Declaración Involucrado
B1: DECLARACIÓN INVOLUCRADO INCIDENTE | L1: Código: | M1: RE-20-12
L2: Versión: | M2: 0
L3: Fecha: | M3: 46100
A5: 1.- ANTECEDENTES PERSONALES
A6: NOMBRE | H6: CARGO
A7: RUT | H7: TELÉFONO
A8: AREA | H8: FECHA
A10: 2.- Declaración del Involucrado (cuando ocurrio)
A17: 3.- Lugar exacto dónde ocurre incidente
A25: 4.- Qué actividad estaba realizando y qué pasó
A28: =------------------------------G28 -> 0
A36: 5.- Otras preguntas que sean necesarias
A44: Declaro que toda la información aquí mencionada es real y fidedigna, realizada de manera voluntaria, permitiendo que este documento sea utilizado para fines investigativos u otros que Servicios Industriales Chome Ltda requiera y estime conveniente, otorgando mi consentimiento en este relato.
J50: ____________________________
I51: FIRMA TRABAJADOR

Sheet Entrevista CPHyS-Ejecutivo-Otro
D2: CUESTIONARIO PARA ACCIDENTADO | G2: Código: | H2: RE-20-3
G3: Versión: | H3: 1
G4: Fecha: | H4: 45691
B7: NOMBRE TRABAJADOR
B8: EDAD
B9: ANTIGÜEDAD EN LA EMPRESA
B10: ANTIGÜEDAD EN PUESTO DE TRABAJO
B11: DIA DEL ACCIDENTE
B12: HORA DEL ACCIDENTE
B13: TURNO
B14: LUGAR DEL ACCIDENTE
B16: DESCRIBA BREVEMENTE LO OCURRIDO
B19: LA TAREA QUE REALIZABA, SE ENCUENTRA EN EL AMBITO DE SUS FUNCIONES Y RESPONSABILIDADES RESPECTO AL CARGO
B21: SI | F21: NO
B23: ¿USTED ESTÁ CAPACITADO PARA EJECUTAR LA TAREA?
B24: SI
B25: ESPECIFICAR:
B26: OJT: | D26: ODI: | F26: FAMILIARIZACIÓN EN PDR:
B27: CURSO AVION: | D27: ESPECIFICAR OTRA:
B30: ¿LA TAREA QUE REALIZABA TIENE UN ESTANDAR DOCUMENTADO? (PROCEDIMIENTO, INSTRUCTIVO, CARTILLA, MANUAL, ETC), SI LA RESPUESTA ES "SI", ESPECIFIQUE CUAL.
B33: ¿USTED CONOCE EL ESTANDAR DOCUMENTADO? (PROCEDIMIENTO, INSTRUCTIVO, CARTILLA, MANUAL, ETC)
B36: ¿LA TAREA PUEDE REALIZARSE SOLO?
B39: ¿CONOCE LOS RIESGOS DE SU LUGAR DE TRABAJO Y LOS ASOCIADOS A LA TAREA?
B42: ¿QUE EPP USABA AL MOMENTO DEL ACCIDENTE? (EPP= ELEMENTOS DE PROTECCIÓN PERSONAL)
B45: ¿QUE MEDIDAS DE SEGURIDAD HABÍA TOMADO PARA REALIZAR SU TRABAJO?
B48: ¿HABLÓ PREVIAMENTE CON SU JEFATURA DIRECTA SOBRE LOS RIESGO DE LA TAREA?
B51: QUE HARÍA PARA QUE ESTE ACCIDENTE NO SE REPITA
B54: A TENIDO OTROS ACCIDENTES O ENFERMEDADES A CAUSA O CON OCASIÓN DEL TRABAJO
B55: SI | F55: NO
B57: HACE CUANTO TIEMPO
B59: DESCRIBA BREVEMENTE LO OCURRIDO
B60: N/A
B65: FIRMA ENTREVISTADO | G65: NOMBRE Y FIRMA ENTREVISTADOR
B67: Fecha Entrevista:

Sheet INVDEF.ACC
F2: INVESTIGACIÓN DE ACCIDENTES E INCIDENTES DEFINITIVA | S2: Código | U2: RE-20-04
S3: Versión | U3: 1
S4: Fecha: | U4: 45691
C6: IDENTIFICACIÓN
C8: FECHA INFORME: | G8: =TODAY() -> 46225 | N8: FECHA ACCIDENTE E INCIDENTE: | R8: ='INV.PRE.ACC'!D40 -> 0
C9: SUB GERENCIA: | G9: ='INV.PRE.ACC'!I9 -> 0 | N9: ÁREA/LUGAR: | Q9: ='INV.PRE.ACC'!I10 -> 0
C10: JEFE DIRECTO/A CARGO: | H10: ='INV.PRE.ACC'!I7 -> 0
C12: CLASIFICACIÓN DEL ACCIDENTE
C14: ACCIDENTE CON LESIÓN AL PERSONAL | M14: INCIDENTE CON DAÑO MATERIAL
C16: Nombre del accidentado: | M16: Equipo - Material - Ambiente dañado
C17: ='INV.PRE.ACC'!D15 -> 0
C18: RUT: | I18: Fecha de Nacimiento
C19: ='INV.PRE.ACC'!D18 -> 0
C20: Edad: | E20: Fecha de ingreso a : | J20: Años en LAN:
C21: =INT((TODAY()-I19)/365) -> 126 | J21: =INT((TODAY()-E21)/365) -> 126
C22: Cargo: | H22: Tiempo en el cargo: | M22: Personal Involucrado
C23: ='INV.PRE.ACC'!D21 -> 0
C24: Dirección: | I24: Comuna:
C26: Estado Civil: | I26: Sexo:
J27: M | L27: F
C30: DESCRIPCIÓN DEL ACCIDENTE E INCIDENTE
C32: ='INV.PRE.ACC'!C29 -> 0
C36: Parte del cuerpo lesionada: | K36: Tipo de accidente e incidente:
C37: ='INV.PRE.ACC'!D35 -> 0
C38: Situación:
C40: Agente causante: | O40: Fuente:
C42: Lugar exacto del accidente e incidente:
C43: ='INV.PRE.ACC'!D24 -> 0
C45: EVALUACIÓN DE RIESGOS
C48: PROBABILIDAD /EXPOSICIÓN
C50: CONSECUENCIA/SEVERIDAD
C52: NIVEL DE RIESGOS | H52: =+IF(AND(H48="Muy Improbable 1",H50="Insignificante 1"),"Bajo",IF(AND(H48="Muy Improbable 1",H50="Bajo 4"),"Bajo",IF(AND(H48="Muy Improbable 1",H50="Moderado 9"),"Bajo",IF(AND(H48="Muy Improbable 1",H50="Significativo 16"),"Moderado",IF(AND(H48="Muy Improbable 1",H50="Catastrofico 25"),"Moderado",IF(AND(H48="Improbable 2",H50="Insignificante 1"),"Bajo",IF(AND(H48="Improbable 2",H50="Bajo 4"),"Bajo",IF(AND(H48="Improbable 2",H50="Moderado 9"),"Moderado",IF(AND(H48="Improbable 2",H50="Significativo 16"),"Moderado",IF(AND(H48="Improbable 2",H50="Catastrofico 25"),"Alto",IF(AND(H48="Remoto 3",H50="Insignificante 1"),"Bajo",IF(AND(H48="Remoto 3",H50="Bajo 4"),"Moderado",IF(AND(H48="Remoto 3",H50="Moderado 9"),"Moderado",IF(AND(H48="Remoto 3",H50="Significativo 16"),"Alto",IF(AND(H48="Remoto 3",H50="Catastrofico 25"),"Alto",IF(AND(H48="Ocasional 4",H50="Insignificante 1"),"Bajo",IF(AND(H48="Ocasional 4",H50="Bajo 4"),"Moderado",IF(AND(H48="Ocasional 4",H50="Moderado 9"),"Alto",IF(AND(H48="Ocasional 4",H50="Significativo 16"),"Alto",IF(AND(H48="Ocasional 4",H50="Catastrofico 25"),"Extremo",IF(AND(H48="Frecuente 5",H50="Insignificante 1"),"Bajo",IF(AND(H48="Frecuente 5",H50="Bajo 4"),"Moderado",IF(AND(H48="Frecuente 5",H50="Moderado 9"),"Alto",IF(AND(H48="Frecuente 5",H50="Significativo 16"),"Extremo",IF(AND(H48="Frecuente 5",H50="Catastrofico 25"),"Extremo"))))))))))))))))))))))))) -> FALSE
C56: MEDIDAS DE CONTROL - PREVENCIÓN
C58: Acción(es) inmediata(s) tomadas por el supervisor: | M58: Responsable:
C59: ='INV.PRE.ACC'!C96 -> 0 | M59: ='INV.PRE.ACC'!U96 -> 0
C63: ANALISIS CAUSAL
C64: REQ. DEL SISTEMA | G64: CAUSAS BASICAS | K64: CAUSAS INMEDITAS | O64: INCIDENTE | S64: DAÑO
C65: ='ANALISIS DE CAUSA'!D20 -> 0 | G65: ='ANALISIS DE CAUSA'!E20 -> 0 | K65: ='ANALISIS DE CAUSA'!F20 -> 0 | O65: ='ANALISIS DE CAUSA'!H20 -> 0 | S65: ='ANALISIS DE CAUSA'!I20 -> 0
C66: ='ANALISIS DE CAUSA'!D21 -> 0 | G66: ='ANALISIS DE CAUSA'!E21 -> 0 | K66: ='ANALISIS DE CAUSA'!F21 -> 0
C67: ='ANALISIS DE CAUSA'!D22 -> 0 | G67: ='ANALISIS DE CAUSA'!E22 -> 0 | K67: ='ANALISIS DE CAUSA'!F22 -> 0
...

Sheet ANALISIS DE CAUSA
D1: ANÁLISIS DE CAUSAS | H1: Código: | I1: RE-20-05
H2: Versión | I2: 1
H3: Fecha: | I3: 45691
B19: Ejemplo | D19: Falta de Procedimientos | E19: Diseño inadecuado y peligroso | F19: Conducir, operar sin autoriz. | H19: Atropello | I19: Lesion Musculoesqueletica

Sheet DIAT
B2: DENUNCIA INDIVIDUAL DE ACCIDENTE DEL TRABAJO (DIAT)
AS4: Folio:
C5: Código del Caso | T5: Fecha de Emisión | AV5: Uso interno
C6: Uso interno
C8: A. Identificación del Empleador
C11: Nombre o Razón Social | AS11: RUT
C14: Dirección (Calle, N°, Depto., Población, Villa, Ciudad) | AF14: Comuna | AZ14: Número de Teléfono
AM17: Hombres | AU17: Mujeres | BB17: Pública | BG17: Privada
C20: Actividad Económica | AG20: N° de Trabajadores | AZ20: Propiedad de la Empresa
AG22: Si es Contratista o Subcontratista, señale actividad económica empresa principal:
E23: Principal | I23: Contratista | O23: Subcontratista | V23: De Servicios Transitorios
C26: Tipo de Empresa
C30: B. Identificación del Trabajador/a
C32: ='INV.PRE.ACC'!D15 -> 0 | AS32: ='INV.PRE.ACC'!D18 -> 0
C33: Nombres - Apellido Paterno - Apellido Materno | AS33: RUN
C35: =INVDEF.ACC!C25 -> 0 | AG35: =INVDEF.ACC!I25 -> 0
C36: Dirección (Calle, N°, Depto., Población, Villa, Ciudad) | AG36: Comuna | AZ36: Número de Teléfono
D39: =INVDEF.ACC!I27 -> 0 | E39: Hombre | H39: =INVDEF.ACC!K27 -> 0 | I39: Mujer | AB39: Señale si el trabajador pertenece o no a un pueblo originario:
C41: Sexo | M41: Edad | Q41: Fecha de Nacimiento | AC41: Alacalufe | AJ41: Colla | AQ41: Quechua | BC41: Otro - Cuál?
AC43: Atacameño | AJ43: Diaguita | AQ43: Rapanui | BB43: ……….……...…………………..
C45: Nacionalidad | M45: Profesión u Oficio | AC45: Aimara | AJ45: Mapuche | AQ45: Yamana (Yagán) | BC45: Ninguno
H49: Días | K49: Meses | O49: Años | U49: Indefinido | AA49: Plazo Fijo | AG49: Por Obra o Faena | AP49: Temporada | BA49: Tipo de Ingreso:
C52: Antigüedad en la Empresa | S52: Tipo de Contrato | BB52: Remuneración Fija
BB54: Remuneración Variable
E58: Empleador | I58: Trabajador Dependiente | R58: Trabajador Independiente | AC58: Familiar no Remunerado | AN58: Trabajador Voluntario | BB58: Honorarios
C60: Categoría Ocupacional
C65: C. Datos del Accidente | V65: ='INV.PRE.ACC'!O40 -> 0 | AA65: A.M. | AE65: P.M. | AJ65: ='INV.PRE.ACC'!D44 -> 0 | AO65: A.M. | AS65: P.M. | AX65: ='INV.PRE.ACC'!L44 -> 0 | BC65: A.M. | BG65: P.M.
L67: Fecha del Accidente | U67: Hora del Accidente | AI67: Hora de Ingreso al Trabajo | AW67: Hora de Salida del Trabajo
C70: Dirección (Calle, N°, Depto., Población, Villa, Ciudad) | AV70: Comuna
C72: Señale qué estaba haciendo el trabajador al momento o justo antes del accidente: | AG72: Señale el lugar donde ocurrió el accidente (nombre de la sección, edificio, área, etc.):
AG74: =INVDEF.ACC!C43 -> 0
C77: Describa ¿Qué pasó o cómo ocurrió el accidente?:
C78: =INVDEF.ACC!C32 -> 0
C82: Señale cuál era su trabajo habitual: | AG82: ¿Al momento del accidente desarrollaba su trabajo habitual?
BF83: Si | BI83: No
C87: Clasificación del Accidente | P87: Tipo de Accidente | AZ87: Tipo de accidente de Trayecto
C88: (Artículo 76 - Ley 16.744):
AE89: Si es accidente de Trayecto, responda:
E90: Grave | I90: Fatal | L90: Otro | R90: Trabajo | W90: Trayecto | BB90: Domicilio - Trabajo
BB94: Trabajo - Domicilio
...

Sheet INF.DIFUSIÓN
D2: INFORMATIVO DE DIFUSIÓN DE ACCIDENTES | K2: Código: | M2: RE-20-06
K3: Versión: | M3: 1
K4: Fecha: | M4: 45691
C6: Caso/DP | G6: Fotografia
C7: Resumen Caso | D7: =INVDEF.ACC!C32 -> 0
C8: Fecha | D8: =INVDEF.ACC!R8 -> 0
C9: Sub Gerencia/área. | D9: =INVDEF.ACC!G9 -> 0
C10: Area: | D10: =INVDEF.ACC!C23 -> 0
C11: Lugar: | D11: ='INV.PRE.ACC'!D24 -> 0
C12: Tipo de Lesión: | D12: ='ANALISIS DE CAUSA'!I20 -> 0
C13: Zona corporal:
C14: Causa Raiz: | G14: Nivel de Riesgo | J14: =INVDEF.ACC!H52 -> FALSE
C16: Recomendaciones | D16: Plan de acción | E16: Responsable | J16: Plazo | L16: Estatus
C17: =INVDEF.ACC!C65 -> 0 | D17: =INVDEF.ACC!C71 -> 0 | E17: =INVDEF.ACC!M71 -> 0 | J17: =INVDEF.ACC!Q71 -> 0 | L17: =INVDEF.ACC!T71 -> 0
C19: =INVDEF.ACC!C66 -> 0 | D19: =INVDEF.ACC!C73 -> 0 | E19: =INVDEF.ACC!M73 -> 0 | J19: =INVDEF.ACC!Q73 -> 0 | L19: =INVDEF.ACC!T73 -> 0
C21: =INVDEF.ACC!C67 -> 0 | D21: =INVDEF.ACC!C75 -> 0 | E21: =INVDEF.ACC!M75 -> 0 | J21: =INVDEF.ACC!Q75 -> 0 | L21: =INVDEF.ACC!T75 -> 0
C23: =INVDEF.ACC!C67 -> 0 | D23: =INVDEF.ACC!C77 -> 0 | E23: =INVDEF.ACC!M77 -> 0 | J23: =INVDEF.ACC!Q77 -> 0 | L23: =INVDEF.ACC!T77 -> 0
B25: SEGURIDAD LABORAL.

Sheet Clasificación
B2: Estatus
B3: Abierto | C3: Refiere a Accidentes aceptados por la mutual pero que no tienen fecha de alta definida
B4: Cerrado | C4: Refiere a Accidentes aceptados por la mutual con fecha de alta definida
B5: En Investigación | C5: Refiere a Accidentes en proceso de evaluación por la mutual.
B6: Rechazado | C6: Refiere a Accidentes rechazados como accidentes laboral por la mutual
B7: Revizar | C7: Refiere a Accidentes de los que no se tiene información legal aún.
B9: Clasificación | C9: Situación | D9: Tipo de Accidente | E9: Fuente Desc/agente causante | F9: Fuente | G9: Zona Corporal
B10: Accidente Laboral | C10: Administrativas de oficina | D10: Atrapamiento entre objetos en movimiento o fijo y movimiento | E10: Advertencias o poco claras o inexistentes (auditiva u visual) | F10: Equipos | G10: Brazos (y/u hombros)
B11: Enfermedad Profesional | C11: Administrativas de Terreno | D11: Atrapamiento por objeto fijo o en movimiento | E11: Conductores eléctricos sin protección o falta de aislación | F11: Equipos | G11: Brazos y Piernas
B12: Reingreso AL | C12: Conducción de vehículos | D12: Atropello | E12: Equipo con partes alteradas o defectuosas | F12: Equipos | G12: Cabeza
B13: Reingreso EP | C13: Excavaciones | D13: Caída a diferente nivel | E13: Equipos sin mantenciones o revisiones de funcionamiento | F13: Equipos | G13: Lumbar
B14: Trayecto | C14: Izamiento de cargas u operaciones de levante (uso de tecles, grúas torre, etc.) | D14: Caída al mismo nivel | E14: Falla en el sistema de aislación | F14: Equipos | G14: Manos (y/o dedos)
C15: Labores de vigilancia y protección industrial | D15: Choque contra elementos móviles | E15: Falta de manual de instrucciones (original) | F15: Equipos | G15: Más de una zona
C16: Labores en espacios confinados | D16: Choque contra objetos o estructura fija | E16: Inexistencia de manuales de operación | F16: Equipos | G16: Ojos
C17: Manejo con objetos calientes o fundidos | D17: Choque por otro vehículo | E17: Protección de maquinaria inexistente o insuficiente | F17: Equipos | G17: Otros
C18: Manejo de Animales | D18: Contacto con electricidad | E18: Sistemas de bloqueo inexistente o desconectados | F18: Equipos | G18: Piernas
C19: Manejo de corto punzantes con material biológico | D19: Contacto con fuego | E19: Almacenamiento incorrecto | F19: Materiales | G19: Pies
C20: Manejo manual de cargas | D20: Contacto con objetos calientes | E20: Envase dañado o con defectos | F20: Materiales | G20: Tronco
C21: Manipulación de herramientas manuales | D21: Contacto con objetos cortantes | E21: Falta de la Hoja de Datos de Seguridad | F21: Materiales
C22: Operación de equipos o herramientas con partes en movimiento | D22: Contacto con objetos punzantes | E22: Falta de rotulación | F22: Materiales
C23: Operación de maquinarias en Superficies (tractor, grúa horquilla) | D23: Contacto con sustancias químicas | E23: Productos incompatibles o reactivos | F23: Materiales
C24: Operación en Terreno | D24: Explosión | E24: Carga de combustible | F24: Ambiente
C25: Operación y/o mantención de equipos energizados | D25: Golpeado con objeto o herramienta | E25: Espacio confinado | F25: Ambiente
C26: Operaciones con sustancias peligrosas | D26: Golpeado contra objetos o equipos | E26: Espacio reducido | F26: Ambiente
C27: Operaciones de Calderas y/o Autoclaves | D27: Golpeado por objeto | E27: Falta de delimitación de pisos | F27: Ambiente
C28: Otros | D28: Incendio | E28: Falta de orden y aseo | F28: Ambiente
C29: Preparación de alimentos | D29: Inmersión | E29: Falta de señalización | F29: Ambiente
C30: Trabajo en altura (igual o superior a 1,8 metros) | D30: Intoxicación por alimentos | E30: Iluminación insuficiente | F30: Ambiente
D31: Picadura o mordedura causado por animal o insecto | E31: Piso fuera de norma o especificaciones | F31: Ambiente
D32: Exposición a manejo manual de carga - Agente Ergonómico | E32: Presencia de gases o agentes peligrosos | F32: Ambiente
B33: SUB GERENCIA | D33: Exposición a mov repetitivo -Agente Ergonómico | E33: Superficies calientes | F33: Ambiente
D34: Exposición a trabajo en altura geográfica - Agente Ergonómico | E34: Manejo manual de carga - Agente Ergonómico | F34: Ambiente Higiénico
D35: Exposición a Ruido | E35: Movimiento repetitivo -Agente Ergonómico | F35: Ambiente Higiénico
B36: Zona/Taller | D36: Exposición a Sílice - Agente Químicos | E36: Trab. altura geográfica - Agente Ergonómico | F36: Ambiente Higiénico
D37: Exposición a polvo - Agentes Químicos | E37: Ruido | F37: Ambiente Higiénico
D38: Exposición a gases - Agentes Químicos | E38: Sílice - Agente Químicos | F38: Ambiente Higiénico
D39: Exposición a vapores - Agentes Químicos | E39: Polvo - Agentes Químicos | F39: Ambiente Higiénico
D40: Exposición a rocíos - Agentes Químicos | E40: Gases - Agentes Químicos | F40: Ambiente Higiénico
D41: Exposición a nieblas - Agentes Químicos | E41: Vapores - Agentes Químicos | F41: Ambiente Higiénico
D42: Exposición a humos metálicos - Agentes Químicos | E42: Rocios - Agentes Químicos | F42: Ambiente Higiénico
...

Sheet Entrevista Testigo
B1: ENTREVISTA TESTIGOS DECLARACIÓN DE HECHOS | L1: Código: | M1: RE-20-07
L2: Versión: | M2: 1
L3: Fecha: | M3: 45691
A5: 1.- ANTECEDENTES PERSONALES
A6: NOMBRE | H6: CARGO
A7: RUT | H7: TELÉFONO
A8: AREA | H8: FECHA
A10: 2.- Declaración del testigo (cuando ocurrio)
A17: 3.- Dónde se encontraba el colaborador
A25: 4.- Qué actividad estaba realizando y qué pasó
A28: =------------------------------G28 -> 0
A36: 5.- Otras preguntas que sean necesarias
A44: Declaro que toda la información aquí mencionada es real y fidedigna, realizada de manera voluntaria, permitiendo que este documento sea utilizado para fines investigativos u otros que Servicios Industriales Chome Ltda requiera y estime conveniente, otorgando mi consentimiento en este relato.
J50: ____________________________
I51: FIRMA TRABAJADOR

Sheet Seguimiento Acc. CTP STP
D1: SEGUIMIENTO Y CONTROL DE INCIDENTE Y/O ACCIDENTES CTP/STP | S1: Código: | T1: RE-20-08
S2: Versión: | T2: 2
S3: Fecha: | T3: 45691
B5: N° | C5: NOMBRE ACCIDENTADO | D5: TIPO CONTRATO | E5: EVIEDENCIA FOTOGARFICA | F5: FECHA | G5: DIAS PERDIDOS | H5: NIVEL ACCIDENTE | I5: ACTIVIDAD QUE REALIZABA / LUGAR | J5: IDENTIFICACION DE GENERO | M5: JEFATURA RESPONSABLE | N5: MEDIDAS DE CONTROL | O5: RESPONSABLE DEL CUMPLIMIENTO | P5: FECHA COMPROMISO | Q5: EVIDENCIA MEJORA | R5: CUMPLIMIENTO
J6: M | K6: H | L6: OTROS | R6: PENDIENTE | S6: EFECTIVO | T6: NEGATIVO
B7: 1
B10: 2
B13: 3
B16: 4
B19: 5
B22: 6
B25: 7
B28: 8

Sheet Seguimiento Incidente daño 
D1: SEGUIMIENTO Y CONTROL DE INCIDENTE CON DAÑO MATERIAL Y/O AMBIENTAL | Q1: Código: | R1: RE-20-09
Q2: Versión: | R2: 2
Q3: Fecha: | R3: 45691
B5: N° | C5: DESCRIPCIÓN DEL INCIDENTE | D5: LUGAR DEL INCIDENTE | E5: EVIDENCIA FOTOGRAFICA | F5: FECHA | G5: NOMBRE OPERADOR O CONDUCTOR | H5: ACTIVIDAD QUE REALIZABA / LUGAR | I5: IDENTIFICACION DEL INCIDENTE | K5: JEFATURA RESPONSABLE | L5: MEDIDAS DE CONTROL | M5: RESPONSABLE DEL CUMPLIMIENTO | N5: FECHA COMPROMISO | O5: EVIDENCIA MEJORA | P5: CUMPLIMIENTO
I6: MATERIAL | J6: AMBIENTAL | P6: PENDIENTE | Q6: EFECTIVO | R6: NEGATIVO
B7: 1
B10: 2
B13: 3
B16: 4
B19: 5
B22: 6
B25: 7
B28: 8

Sheet Reporte Cuasi Accidente
B1: REPORTE DE CUASI ACCIDENTE | D1: Código: | E1: RE-20-11
D2: Versión: | E2: 1
D3: Fecha: | E3: 45691
B4: CUASI-ACCIDENTE: Eventos no programados que bajo circunstancias ligeramente diferentes podrían haber ocasionado lesión a las personas, daño a los equipos, materiales y/o Medio Ambiente de la Planta u Oficina. No existe lesión ni daño a la propiedad
B5: SI EL EVENTO QUE ANALIZARA CONSIDERA LESIONES Y DAÑO A LA PROPIEDAD UTILICE FORMULARIO INVESTIGACION DE ACCIDENTES
B6: CENTRO DE TRABAJO: AREA:
B7: PERSONA QUIEN INFORMA EL CUASI ACCIDENTE:
B8: FECHA EN QUE SE INFORMA:
B9: FECHA EN QUE SUCEDIÓ EL CUASI ACCIDENTE: HORA :
B10: DESCRIBIR CLARAMENTE COMO SUCEDIÓ EL CUASI ACCIDENTE:
B16: ACCIONES TOMADAS PARA EVITAR SU OCURRENCIA
