Workbook
Name L_TIPO_EVENTO: OFFSET('Clasificación'!$B$12,0,0,COUNTA('Clasificación'!$B$12:$B$200),1)
Name L_CLASIF: OFFSET('Clasificación'!$C$12,0,0,COUNTA('Clasificación'!$C$12:$C$200),1)
Name L_POTENCIAL: OFFSET('Clasificación'!$D$12,0,0,COUNTA('Clasificación'!$D$12:$D$200),1)
Name L_ESTATUS: OFFSET('Clasificación'!$E$12,0,0,COUNTA('Clasificación'!$E$12:$E$200),1)
Name L_SITUACION: OFFSET('Clasificación'!$H$12,0,0,COUNTA('Clasificación'!$H$12:$H$200),1)
Name L_TIPO_ACC: OFFSET('Clasificación'!$I$12,0,0,COUNTA('Clasificación'!$I$12:$I$200),1)
Name L_AGENTE: OFFSET('Clasificación'!$J$12,0,0,COUNTA('Clasificación'!$J$12:$J$200),1)
Name L_FUENTE: OFFSET('Clasificación'!$L$12,0,0,COUNTA('Clasificación'!$L$12:$L$200),1)
Name L_ZONA: OFFSET('Clasificación'!$M$12,0,0,COUNTA('Clasificación'!$M$12:$M$200),1)
Name L_DANOS: OFFSET('Clasificación'!$N$12,0,0,COUNTA('Clasificación'!$N$12:$N$200),1)
Name L_TEMP: OFFSET('Clasificación'!$P$12,0,0,COUNTA('Clasificación'!$P$12:$P$200),1)
Name L_CLIMA: OFFSET('Clasificación'!$Q$12,0,0,COUNTA('Clasificación'!$Q$12:$Q$200),1)
Name L_TURNOS: OFFSET('Clasificación'!$R$12,0,0,COUNTA('Clasificación'!$R$12:$R$200),1)
Name L_LUGAR: OFFSET('Clasificación'!$S$12,0,0,COUNTA('Clasificación'!$S$12:$S$200),1)
Name L_HECHOS: OFFSET('Clasificación'!$U$12,0,0,COUNTA('Clasificación'!$U$12:$U$200),1)
Name L_RELACION: OFFSET('Clasificación'!$V$12,0,0,COUNTA('Clasificación'!$V$12:$V$200),1)
Name L_CONTROL: OFFSET('Clasificación'!$W$12,0,0,COUNTA('Clasificación'!$W$12:$W$200),1)
Name L_CORR_PREV: OFFSET('Clasificación'!$X$12,0,0,COUNTA('Clasificación'!$X$12:$X$200),1)
Name L_ALCANCE: OFFSET('Clasificación'!$Y$12,0,0,COUNTA('Clasificación'!$Y$12:$Y$200),1)
Name L_PRIORIDAD: OFFSET('Clasificación'!$Z$12,0,0,COUNTA('Clasificación'!$Z$12:$Z$200),1)
Name L_ESTADO: OFFSET('Clasificación'!$AA$12,0,0,COUNTA('Clasificación'!$AA$12:$AA$200),1)
Name L_EFICACIA: OFFSET('Clasificación'!$AB$12,0,0,COUNTA('Clasificación'!$AB$12:$AB$200),1)
Name L_RIESGO: OFFSET('Clasificación'!$AC$12,0,0,COUNTA('Clasificación'!$AC$12:$AC$200),1)
Name L_EVIDENCIA: OFFSET('Clasificación'!$AE$12,0,0,COUNTA('Clasificación'!$AE$12:$AE$200),1)
Name L_CALIDAD: OFFSET('Clasificación'!$AF$12,0,0,COUNTA('Clasificación'!$AF$12:$AF$200),1)
Name L_ROL: OFFSET('Clasificación'!$AG$12,0,0,COUNTA('Clasificación'!$AG$12:$AG$200),1)
Name L_CUMPLE: OFFSET('Clasificación'!$AH$12,0,0,COUNTA('Clasificación'!$AH$12:$AH$200),1)
Name L_REVISION: OFFSET('Clasificación'!$AI$12,0,0,COUNTA('Clasificación'!$AI$12:$AI$200),1)
Name L_CPHS: OFFSET('Clasificación'!$AJ$12,0,0,COUNTA('Clasificación'!$AJ$12:$AJ$200),1)
Name L_SINO: OFFSET('Clasificación'!$AL$12,0,0,COUNTA('Clasificación'!$AL$12:$AL$200),1)
Name L_SNV: OFFSET('Clasificación'!$AM$12,0,0,COUNTA('Clasificación'!$AM$12:$AM$200),1)
Name L_SNNA: OFFSET('Clasificación'!$AN$12,0,0,COUNTA('Clasificación'!$AN$12:$AN$200),1)
Name L_AUTORIZ: OFFSET('Clasificación'!$AO$12,0,0,COUNTA('Clasificación'!$AO$12:$AO$200),1)
Name L_SEXO: OFFSET('Clasificación'!$AP$12,0,0,COUNTA('Clasificación'!$AP$12:$AP$200),1)

Sheet PASO A PASO
G3: PASO A PASO EN LA OCURRENCIA DE UN INCIDENTE/ACCIDENTE LABORAL | Y3: Código: | Z3: RE-20-01
Y4: Versión: | Z4: 3
Y5: Fecha: | Z5: 46314
B7: Pasos a seguir cuando ocurre un ACCIDENTE LABORAL. | N7: NOTA: EN CASO DE ACCIDENTE DE TRAYECTO CUMPLIR ÍTEMS 1, 2 Y 3. EN CASO DE ACCIDENTE GRAVE O FATAL: SUSPENDER DE INMEDIATO LA FAENA AFECTADA E INFORMAR A LA INSPECCIÓN DEL TRABAJO, A LA SEREMI DE SALUD Y AL ORGANISMO ADMINISTRADOR.
A9: ACTIVIDAD | L9: RESPONSABLE | Q9: PLAZO | Y9: FORMULARIO/DOCUMENTO DE ENTREGA | Z9: INFORME DERIVADO A:
A10: 1 | B10: INFORMAR Y RECOPILAR DATOS PARA INVESTIGACIÓN PRELIMINAR DE ACCIDENTE EN SU TURNO | L10: JEFE DE TERRENO O SUPERVISOR | Q10: INMEDIATO | Y10: CORREO O LLAMADO CELULAR | Z10: ADMINISTRADOR DE CONTRATO PREVENCION DE RIESGO
A14: 2 | B14: INFORMAR EL INCIDENTE /ACCIDENTE | L14: PREVENCION DE RIESGOS | Q14: INMEDIATO | Y14: CORREO O LLAMADO CELULAR | Z14: JEFE DPTO. PREVENCION DE RIESGOS
A16: 3 | B16: REALIZAR Y ENVIAR INVESTIGACION PRELIMINAR DE ACCIDENTE. | L16: JEFE DE TERRENO o SUPERVISOR PREVENCIÓN DE RIESGOS (Envia el correo) | Q16: CONSOLIDAR ANTECEDENTES Y REALIZAR INFORME: INMEDIATA 3 HORAS DE OCURRIDO EL ACCIDENTE E INCIDENTE | Y16: RE-20-02
Z17: GERENTE GENERAL
Z18: TODAS LAS SUBGERENCIAS
Z19: JEFE DPTO. PREVENCIÓN DE RIESGOS
Z20: ADMINISTRADOR DE CONTRATO
Z21: COMITÉ PARITARIO
Z22: TODOS LOS CORREOS DE PREVENCIÓN
Z23: DE RIESGOS
A25: 4 | B25: ENTREVISTA A TESTIGOS | L25: COMISIÓN INVESTIGACIÓN ACCIDENTES COMITÉ PARITARIO PREVENCION DE RIESGOS JEFE DE TERRENO O SUPERVISOR | Q25: 5 hrs DESPUES DE OCURRIDO EL ACCIDENTE E INCIDENTE | Y25: RE-20-07 DECLARACIÓN INDIVIDUAL | Z25: ADMINISTRADOR DE CONTRATO PREVENCION DE RIESGO COMITÉ PARITARIO
A27: 5 | B27: REALIZACIÓN DIAT | L27: ADMINISTRADOR DE CONTRATO (FIRMA) PREVENCION DE RIESGOS | Q27: MAXIMO 24 HORAS OCURRIDO EL ACCIDENTE E INCIDENTE
Z28: MUTUALIDAD
Y29: DIAT | Z29: GERENTE GENERAL
Z30: JEFE DPTO. PREVENCIÓN DE RIESGOS
A32: 6 | B32: ENTREVISTA AL ACCIDENTADO | L32: COMITÉ PARITARIO | Q32: DESDE EL MOMENTO DEL ENVÍO DEL INFORME PRE LIMINAR 24 HORAS. | Y32: RE-20-03
Z33: GERENTE GENERAL
B34: CONTAR CON LA INFORMACIÓN DIRECTA DEL ACCIDENTADO POR MEDIO DE ESTA HERRAMIENTA A REALIZAR EN FORMA PRESENCIAL O TELEFONICA, DEL PORQUE DE LA OCURRENCIA DEL ACCIDENTE. | Z34: TODAS LAS SUBGERENCIAS
Z35: JEFE DPTO. PREVENCIÓN DE RIESGOS
Z36: ADMINISTRADOR DE CONTRATO
Z37: JEFE TERRENO
A38: 7 | B38: INVESTIGACIÓN DEFINITIVA CON ÁRBOL DE CAUSAS: | L38: EQUIPO INVESTIGADOR: PREVENCIÓN DE RIESGOS FAENA (RESPONSABLE), COMITÉ PARITARIO Y JEFE DE TERRENO | Y38: RE-20-04 INVESTIGACIÓN DEFINITIVA RE-20-05 ÁRBOL DE CAUSAS
Q39: 72 HORAS DE LA RECEPCIÓN DE INVESTIGACIÓN PRE LIMINAR | Z39: GERENTE GENERAL
B40: LISTAR HECHOS VERIFICABLES Y CONSTRUIR EL ÁRBOL DE CAUSAS. | L40: ADMINISTRADOR DE CONTRATO/JEFE TERRENO | Z40: TODAS LAS SUBGERENCIAS
B41: IDENTIFICAR CAUSAS RAÍZ Y DEFINIR MEDIDAS POR JERARQUÍA DE CONTROLES. | L41: PREVENCIÓN DE RIESGOS | Z41: JEFE DPTO. PREVENCION DE RIESGOS
B42: DEFINIR RESPONSABLES, PLAZOS, EVIDENCIA Y VERIFICADOR DE CADA MEDIDA. | L42: SUBGERENCIA DEL AREA
B43: REVISAR MATRIZ IPER E INSTRUMENTOS PREVENTIVOS Y GENERAR INFORME DEFINITIVO. | Z43: COMITÉ PARITARIO
B44: REVISIÓN DE CALIDAD Y APROBACIÓN DE LA JEFA DPTO. PREVENCIÓN DE RIESGOS (RE-20-13). | L44: (Adm. De contrato envia el correo)
A45: 8 | Y45: RE-20-06 INFORMATIVO DE DIFUSIÓN, BRIEFING DE SEGURIDAD, ALERTA DE PELIGRO Y REGISTRO DE ASISTENCIA
B46: DIFUNDIR MEDIDAS CORRECTIVAS TRANSITORIAS/DEFINITIVAS Y MEJORAS A REALIZAR | L46: COMITÉ PARITARIO | Q46: 24 HORAS DESPUÉS DE APROBADA LA REVISIÓN DE CALIDAD | Z46: GERENTE GENERAL
L47: ADMINISTRADOR DE CONTRATO/JEFE TERRENO | Z47: TODAS LAS SUBGERENCIAS
Z48: JEFE DPTO. PREVENCIÓN DE RIESGOS
L49: PREVENCIÓN DE RIESGOS (registro de asistencia e informativo de difusión) | Z49: ADMINISTRADOR DE CONTRATO
L50: (todos difunden) | Z50: COMITÉ PARITARIO
A51: 9 | B51: REUNIÓN POST ACCIDENTES
...

Sheet INV.PRE.ACC
F3: INVESTIGACIÓN PRELIMINAR DE ACCIDENTES E INCIDENTES | T3: Código | V3: RE-20-02
T4: Versión | V4: 2
T5: Fecha: | V5: 46314
C7: NOMBRE JEFATURA A CARGO:
C8: FECHA INFORME:
C9: SUB GERENCIA:
C10: AREA/TALLER:
C12: IDENTIFICACIÓN DEL ACCIDENTADO/ PERSONAL INVOLUCRADO EN EL INCIDENTE
C14: 1.- | D14: NOMBRE:
C17: 2.- | D17: RUT:
C20: 3.- | D20: CARGO:
C23: 4.- | D23: LUGAR EXACTO DEL ACCIDENTE:
C26: CLASIFICACIÓN DEL ACCIDENTE/INCIDENTE.
C27: TIPO DE EVENTO: | Q27: POTENCIAL:
C28: 5.- | D28: DESCRIPCIÓN DE LO OCURRIDO:
C34: 6.- | D34: PARTE DEL CUERPO LESIONADA. | N34: 8.- | O34: QUE ELEMENTO(S) PROVOCA LA LESIÓN
C37: DATOS
C39: 9.- | D39: FECHA DEL ACCIDENTE E INCIDENTE: | N39: 10.- | O39: HORA DEL ACCIDENTE E INCIDENTE:
C42: 11.- | D42: HORA DE INGRESO/SALIDA DE TURNO:
C44: I: | K44: S:
C48: 12.- | D48: OTROS ANTECEDENTES Y/O DETALLE DE INFORMACION ANEXA | P48: (LISTAS DESPLEGABLES EN CADA ITEM)
C51: PELIGRO O FUENTE
C52: Especificar Otros:
C54: TEMPERATURAS
C56: CLIMA
C58: SISTEMA DE TURNOS
C64: QUE DESVIACIONES A LOS PROCEDIMIENTOS, EN LOS EQUIPOS O EN EL ENTORNO SEGÚN SU EVALUACIÓN GENERARON LA OCURRENCIA DEL ACCIDENTE E INCIDENTE
C71: FOTOGRAFÍA
C94: ACCIONES INMEDIATAS REALIZADAS (marque con X y detalle abajo)
C95: ACCIÓN | U95: RESPONSABLE
C96: Primeros auxilios / derivación asistencial | L96: Aislamiento del área
C97: Suspensión de la tarea o faena | L97: Preservación de evidencias
C98: Aviso a jefatura y Prevención de Riesgos | L98: Aviso al Comité Paritario
C99: Aviso al organismo administrador | L99: Aviso a la autoridad (accidente grave o fatal)
C100: Detalle:
C101: QUE MEDIDA(S) CREE USTED QUE SE DEBERÍA(N) REALIZAR PARA LA NO REPETICIÓN DEL ACCIDENTE E INCIDENTE OCURRIDO.
C103: 1
C106: 2

Sheet DECLARACIÓN INDIVIDUAL
D2: DECLARACIÓN INDIVIDUAL PARA LA INVESTIGACIÓN (involucrado, testigo o persona accidentada) | K2: Código | L2: RE-20-07
K3: Versión | L3: 2
K4: Fecha | L4: 46314
B6: Investigación N° | H6: Fecha de la entrevista
B7: Nombre de quien declara | H7: RUT / identificación
B8: Cargo / relación con el evento | H8: Contacto
B9: Calidad | H9: Lugar de la entrevista
B10: Entrevistador(es)
B12: Reglas de entrevista: entrevista a cada persona por separado, en un lugar tranquilo y sin inducir respuestas. Pide primero un relato libre y luego aclara secuencia, posiciones, comunicaciones, condiciones y cambios. Distingue lo que la persona vio, oyó, hizo o supone.
B14: 1. RELATO LIBRE DE LO OBSERVADO, REALIZADO O CONOCIDO
B25: 2. ACLARACIONES SOLICITADAS POR EL EQUIPO INVESTIGADOR
B32: 3. INFORMACIÓN COMPLEMENTARIA
B33: Marque lo que corresponda | K33: Sí / No
B34: Presenció directamente el evento
B35: Participó en la tarea
B36: Conocía el proceso
B37: Recibió información de terceros
B38: Adjunta croquis
B39: Adjunta fotografías
B40: Autoriza contacto para aclaraciones
B41: Solicita reserva de identidad en la difusión interna
B43: Declaro que la información precedente corresponde a mi conocimiento y recuerdo de los hechos. Se me informó que esta declaración será utilizada solo con fines preventivos y para la gestión del accidente ante el organismo administrador y la autoridad, y que se mantendrá bajo resguardo por su carácter confidencial.
B48: Nombre y firma de quien declara | F48: Nombre y firma del entrevistador | J48: Fecha

Sheet Entrevista CPHyS-Ejecutivo-Otro
D2: CUESTIONARIO PARA ACCIDENTADO | G2: Código: | H2: RE-20-03
G3: Versión: | H3: 2
G4: Fecha: | H4: 46314
B7: NOMBRE TRABAJADOR
B8: CARGO
B9: ANTIGÜEDAD EN LA EMPRESA
B10: ANTIGÜEDAD EN PUESTO DE TRABAJO
B11: DIA DEL ACCIDENTE
B12: HORA DEL ACCIDENTE
B13: TURNO
B14: LUGAR DEL ACCIDENTE
B16: DESCRIBA BREVEMENTE LO OCURRIDO
B19: LA TAREA QUE REALIZABA, SE ENCUENTRA EN EL AMBITO DE SUS FUNCIONES Y RESPONSABILIDADES RESPECTO AL CARGO
B21: SI | F21: NO
B23: ¿USTED ESTÁ CAPACITADO PARA EJECUTAR LA TAREA?
B24: SI
B25: ESPECIFICAR:
B26: OJT: | D26: ODI: | F26: FAMILIARIZACIÓN EN PDR:
B27: LICENCIA O AUTORIZACIÓN: | D27: ESPECIFICAR OTRA:
B30: ¿LA TAREA QUE REALIZABA TIENE UN ESTANDAR DOCUMENTADO? (PROCEDIMIENTO, INSTRUCTIVO, CARTILLA, MANUAL, ETC), SI LA RESPUESTA ES "SI", ESPECIFIQUE CUAL.
B33: ¿USTED CONOCE EL ESTANDAR DOCUMENTADO? (PROCEDIMIENTO, INSTRUCTIVO, CARTILLA, MANUAL, ETC)
B36: ¿LA TAREA PUEDE REALIZARSE SOLO?
B39: ¿CONOCE LOS RIESGOS DE SU LUGAR DE TRABAJO Y LOS ASOCIADOS A LA TAREA?
B42: ¿QUÉ EPP USABA AL MOMENTO DEL ACCIDENTE? ¿LE QUEDABA BIEN (TALLA Y AJUSTE)?
B45: ¿QUE MEDIDAS DE SEGURIDAD HABÍA TOMADO PARA REALIZAR SU TRABAJO?
B48: ¿HABLÓ PREVIAMENTE CON SU JEFATURA DIRECTA SOBRE LOS RIESGO DE LA TAREA?
B51: QUE HARÍA PARA QUE ESTE ACCIDENTE NO SE REPITA
B54: ¿QUÉ FUE DISTINTO ESE DÍA RESPECTO DE CÓMO SE HACE HABITUALMENTE LA TAREA? (EQUIPO, MATERIALES, PERSONAL, HORARIO, INSTRUCCIONES)
B57: ¿QUÉ NECESITABA PARA HACER LA TAREA DE FORMA SEGURA Y NO TENÍA?
B65: FIRMA ENTREVISTADO | G65: NOMBRE Y FIRMA ENTREVISTADOR
B67: Fecha Entrevista:

Sheet INV.DEF.ACC
D2: INVESTIGACIÓN DEFINITIVA DE ACCIDENTES E INCIDENTES Metodología árbol de causas (D.S. N°44) | K2: Código | L2: RE-20-04
K3: Versión | L3: 2
K4: Fecha | L4: 46314
B6: Criterio central: la investigación busca hechos y condiciones causales, no culpables. Los datos sensibles o médicos se registran solo si son indispensables y quedan con acceso restringido. Esta hoja no reemplaza la DIAT ni los procedimientos especiales para accidentes graves o fatales.
B8: 1. IDENTIFICACIÓN DEL EVENTO
B9: Fecha del informe | H9: Fecha del evento | K9: =IF('INV.PRE.ACC'!D40="","",'INV.PRE.ACC'!D40)
B10: Hora del evento | E10: =IF('INV.PRE.ACC'!O40="","",'INV.PRE.ACC'!O40) | H10: Jefatura a cargo | K10: =IF('INV.PRE.ACC'!I7="","",'INV.PRE.ACC'!I7)
B11: Subgerencia | E11: =IF('INV.PRE.ACC'!I9="","",'INV.PRE.ACC'!I9) | H11: Área / taller | K11: =IF('INV.PRE.ACC'!I10="","",'INV.PRE.ACC'!I10)
B12: Faena / centro de trabajo | H12: N° DIAT / registro
B13: Lugar exacto | E13: =IF('INV.PRE.ACC'!D24="","",'INV.PRE.ACC'!D24)
B14: Tipo de evento | E14: =IF('INV.PRE.ACC'!I27="","",'INV.PRE.ACC'!I27) | H14: Potencial del evento | K14: =IF('INV.PRE.ACC'!T27="","",'INV.PRE.ACC'!T27)
B15: Situación | H15: Tipo de accidente
B16: Agente causante | H16: Fuente
B18: 2. PERSONA AFECTADA O INVOLUCRADA
B19: Nombre | E19: =IF('INV.PRE.ACC'!D15="","",'INV.PRE.ACC'!D15) | H19: RUT | K19: =IF('INV.PRE.ACC'!D18="","",'INV.PRE.ACC'!D18)
B20: Cargo | E20: =IF('INV.PRE.ACC'!D21="","",'INV.PRE.ACC'!D21) | H20: Sexo (registro estadístico)
B21: Antigüedad en la empresa | H21: Experiencia en la tarea
B22: Jornada / turno | H22: Horas trabajadas antes del evento
B23: Tipo de contrato | H23: Jefatura directa
B24: Capacitación para la tarea | H24: Autorización o licencia
B25: ODI / información de riesgos | H25: Procedimiento conocido
B26: EPP requerido | H26: EPP utilizado
B27: Parte del cuerpo lesionada | E27: =IF('INV.PRE.ACC'!D35="","",'INV.PRE.ACC'!D35) | H27: Lesión (descripción general)
B28: Los antecedentes clínicos detallados no se registran aquí: se guardan en anexo confidencial.
B30: 3. ENFOQUE DE GÉNERO E INCLUSIÓN
B31: Registra solo factores que influyeron en la exposición o en la consecuencia: talla o ajuste de EPP, diseño antropométrico del puesto, asignación de tareas, embarazo o lactancia conocidos, responsabilidades de cuidado que afecten la jornada, barreras de comunicación o discapacidad. No registres información personal innecesaria.
B35: 4. EQUIPO INVESTIGADOR Y PARTICIPACIÓN
B36: Nombre | E36: Cargo / representación | G36: Rol en la investigación | I36: Participó en visita | J36: Declaración de imparcialidad | L36: Firma
B43: Observaciones sobre participación o conflictos de interés
B45: 5. EVIDENCIAS
B46: N° | C46: Tipo | E46: Descripción / identificación | I46: Origen | K46: Fecha | L46: Custodia / ubicación
B47: 1
B48: 2
B49: 3
B50: 4
B51: 5
B52: 6
B53: 7
B54: 8
B55: 9
...

Sheet ÁRBOL DE CAUSAS
D2: ÁRBOL DE CAUSAS (listado de hechos, relaciones y trayectorias) | K2: Código | L2: RE-20-05
K3: Versión | L3: 2
K4: Fecha | L4: 46314
B6: Cómo construir el árbol: parte desde el hecho final (H1 = lesión o daño) y pregunta para cada hecho: ¿qué fue necesario para que ocurriera? ¿fue suficiente por sí solo? ¿fue necesario algo más? Continúa hasta que no existan antecedentes verificables. La investigación busca hechos y condiciones, no culpables.
B8: 7. LISTADO DE HECHOS
B9: Un hecho válido es breve, verificable y afirmativo, y cada frase contiene un solo hecho. Ejemplo adecuado: «El resguardo fijo de la transmisión estaba retirado». Ejemplo inadecuado: «El trabajador actuó irresponsablemente». H1 es el hecho final.
B10: ID | C10: Hecho objetivo | I10: Fuente que lo respalda | L10: ¿Causal? | M10: ¿Requiere verificación?
B11: H1
B12: H2
B13: H3
B14: H4
B15: H5
B16: H6
B17: H7
B18: H8
B19: H9
B20: H10
B21: H11
B22: H12
... B32: 7.1 VARIACIONES RESPECTO DEL TRABAJO HABITUAL Y BARRERAS
B33: Aspecto | D33: Condición esperada | F33: Condición real | H33: Control existente | J33: Falla o ausencia del control
B34: Persona / dotación
B35: Tarea / método
B36: Equipo / herramienta
B37: Material / energía
B38: Entorno / lugar
B39: Organización / supervisión
B40: Información / capacitación
B41: Emergencia / respuesta
B43: 8.1 MATRIZ DE RELACIONES CAUSALES
B44: Cadena: un hecho tiene un único antecedente. Conjunción: dos o más hechos debieron concurrir para producir el mismo hecho. Independiente: un mismo hecho origina dos o más consecuencias. Usa solo IDs del listado de hechos.
B45: N° | C45: Hecho antecedente (ID) | D45: Relación | F45: Hecho consecuencia (ID) | G45: Justificación factual | L45: ¿Causa raíz?
B46: 1
B47: 2
B48: 3
B49: 4
B50: 5
B51: 6
B52: 7
B53: 8
...

Sheet REVISIÓN DE CALIDAD
D2: LISTA DE VERIFICACIÓN DE CALIDAD DE LA INVESTIGACIÓN | K2: Código | L2: RE-20-13
K3: Versión | L3: 1
K4: Fecha | L4: 46314
B6: La aplica la Jefa Dpto. Prevención de Riesgos antes de aprobar el informe definitivo (RE-20-04) y antes de la difusión (RE-20-06).
B7: Investigación N° | H7: Fecha del evento | K7: =IF('INV.DEF.ACC'!K9="","",'INV.DEF.ACC'!K9)
B9: N° | C9: Criterio | E9: Verificación | J9: Resultado | L9: Observación / corrección
B10: 1 | C10: Oportunidad | E10: La investigación se inició prontamente y se preservaron las evidencias disponibles.
B11: 2 | C11: Participación | E11: Se incorporó a personas trabajadoras y sus representantes, con enfoque de género e inclusión.
B12: 3 | C12: Objetividad | E12: El relato y los hechos no contienen juicios de valor, culpabilización ni suposiciones no identificadas.
B13: 4 | C13: Trazabilidad | E13: Cada hecho relevante se respalda con una fuente o evidencia.
B14: 5 | C14: Coherencia | E14: Relato, línea de tiempo, listado de hechos y árbol son consistentes entre sí.
B15: 6 | C15: Profundidad | E15: El análisis no se detuvo en «error humano» y alcanzó condiciones técnicas u organizacionales.
B16: 7 | C16: Causas raíz | E16: Las causas raíz corresponden a hechos sin antecedentes causales verificables adicionales.
B17: 8 | C17: Medidas | E17: Cada causa raíz tiene al menos una medida específica, viable y priorizada por jerarquía de control.
B18: 9 | C18: Planificación | E18: Las medidas tienen responsable, plazo, recursos, evidencia y verificador.
B19: 10 | C19: IPER | E19: Se revisó la necesidad de actualizar la matriz IPER y otros instrumentos preventivos.
B20: 11 | C20: Eficacia | E20: Se definió cómo y cuándo se evaluará la eficacia y el riesgo residual.
B21: 12 | C21: Confidencialidad | E21: Los antecedentes personales, médicos y declaraciones están bajo acceso restringido.
B22: 13 | C22: Registro | E22: El informe y sus anexos están foliados, respaldados y disponibles para las entidades competentes.
B24: REVISIÓN FINAL
B25: Revisado por | H25: Cargo | K25: Jefa Dpto. Prevención de Riesgos
B26: Resultado | H26: Fecha
B27: Observaciones finales
B28: Firma

Sheet DIAT
B2: DENUNCIA INDIVIDUAL DE ACCIDENTE DEL TRABAJO (DIAT)
AS4: Folio:
C5: Código del Caso | T5: Fecha de Emisión | AV5: Uso interno
C6: Uso interno
C8: A. Identificación del Empleador
C11: Nombre o Razón Social | AS11: RUT
C14: Dirección (Calle, N°, Depto., Población, Villa, Ciudad) | AF14: Comuna | AZ14: Número de Teléfono
AM17: Hombres | AU17: Mujeres | BB17: Pública | BG17: Privada
C20: Actividad Económica | AG20: N° de Trabajadores | AZ20: Propiedad de la Empresa
AG22: Si es Contratista o Subcontratista, señale actividad económica empresa principal:
E23: Principal | I23: Contratista | O23: Subcontratista | V23: De Servicios Transitorios
C26: Tipo de Empresa
C30: B. Identificación del Trabajador/a
C32: ='INV.PRE.ACC'!D15 | AS32: ='INV.PRE.ACC'!D18
C33: Nombres - Apellido Paterno - Apellido Materno | AS33: RUN
C36: Dirección (Calle, N°, Depto., Población, Villa, Ciudad) | AG36: Comuna | AZ36: Número de Teléfono
D39: =IF('INV.DEF.ACC'!K20="Hombre","X","") | E39: Hombre | H39: =IF('INV.DEF.ACC'!K20="Mujer","X","") | I39: Mujer | AB39: Señale si el trabajador pertenece o no a un pueblo originario:
C41: Sexo | M41: Edad | Q41: Fecha de Nacimiento | AC41: Alacalufe | AJ41: Colla | AQ41: Quechua | BC41: Otro - Cuál?
AC43: Atacameño | AJ43: Diaguita | AQ43: Rapanui | BB43: ……….……...…………………..
C45: Nacionalidad | M45: Profesión u Oficio | AC45: Aimara | AJ45: Mapuche | AQ45: Yamana (Yagán) | BC45: Ninguno
H49: Días | K49: Meses | O49: Años | U49: Indefinido | AA49: Plazo Fijo | AG49: Por Obra o Faena | AP49: Temporada | BA49: Tipo de Ingreso:
C52: Antigüedad en la Empresa | S52: Tipo de Contrato | BB52: Remuneración Fija
BB54: Remuneración Variable
E58: Empleador | I58: Trabajador Dependiente | R58: Trabajador Independiente | AC58: Familiar no Remunerado | AN58: Trabajador Voluntario | BB58: Honorarios
C60: Categoría Ocupacional
C65: C. Datos del Accidente | V65: ='INV.PRE.ACC'!O40 | AA65: A.M. | AE65: P.M. | AJ65: ='INV.PRE.ACC'!D44 | AO65: A.M. | AS65: P.M. | AX65: ='INV.PRE.ACC'!L44 | BC65: A.M. | BG65: P.M.
L67: Fecha del Accidente | U67: Hora del Accidente | AI67: Hora de Ingreso al Trabajo | AW67: Hora de Salida del Trabajo
C70: Dirección (Calle, N°, Depto., Población, Villa, Ciudad) | AV70: Comuna
C72: Señale qué estaba haciendo el trabajador al momento o justo antes del accidente: | AG72: Señale el lugar donde ocurrió el accidente (nombre de la sección, edificio, área, etc.):
AG74: =IF('INV.PRE.ACC'!D24="","",'INV.PRE.ACC'!D24)
C77: Describa ¿Qué pasó o cómo ocurrió el accidente?:
C78: =IF('INV.PRE.ACC'!C29="","",'INV.PRE.ACC'!C29)
C82: Señale cuál era su trabajo habitual: | AG82: ¿Al momento del accidente desarrollaba su trabajo habitual?
BF83: Si | BI83: No
C87: Clasificación del Accidente | P87: Tipo de Accidente | AZ87: Tipo de accidente de Trayecto
C88: (Artículo 76 - Ley 16.744):
AE89: Si es accidente de Trayecto, responda:
E90: Grave | I90: Fatal | L90: Otro | R90: Trabajo | W90: Trayecto | BB90: Domicilio - Trabajo
BB94: Trabajo - Domicilio
E98: Parte de Carabineros | M98: Declaración | S98: Testigos | X98: Otro | BB98: Enttre dos Trabajos
...

Sheet INF.DIFUSIÓN
D2: INFORMATIVO DE DIFUSIÓN DE ACCIDENTES | K2: Código: | M2: RE-20-06
K3: Versión: | M3: 2
K4: Fecha: | M4: 46314
C6: Caso/DP | G6: Fotografia
C7: Resumen Caso | D7: =IF('INV.DEF.ACC'!B70="",IF('INV.PRE.ACC'!C29="","",'INV.PRE.ACC'!C29),'INV.DEF.ACC'!B70)
C8: Fecha | D8: =IF('INV.DEF.ACC'!K9="","",'INV.DEF.ACC'!K9)
C9: Sub Gerencia/área. | D9: =IF('INV.DEF.ACC'!E11="","",'INV.DEF.ACC'!E11)
C10: Area: | D10: =IF('INV.DEF.ACC'!K11="","",'INV.DEF.ACC'!K11)
C11: Lugar: | D11: =IF('INV.DEF.ACC'!E13="","",'INV.DEF.ACC'!E13)
C12: Lesión: | D12: =IF('INV.DEF.ACC'!K27="","",'INV.DEF.ACC'!K27)
C13: Zona corporal: | D13: =IF('INV.DEF.ACC'!E27="","",'INV.DEF.ACC'!E27)
C14: Causas raíz y medidas: | G14: Potencial del evento | J14: =IF('INV.DEF.ACC'!K14="","",'INV.DEF.ACC'!K14)
C16: Causa raíz | D16: Medida | E16: Responsable | J16: Plazo | L16: Estatus
C17: =IF('INV.DEF.ACC'!C92="","",'INV.DEF.ACC'!C92) | D17: =IF('INV.DEF.ACC'!F92="","",'INV.DEF.ACC'!F92) | E17: =IF('INV.DEF.ACC'!F114="","",'INV.DEF.ACC'!F114) | J17: =IF('INV.DEF.ACC'!H114="","",'INV.DEF.ACC'!H114) | L17: =IF('INV.DEF.ACC'!I114="","",'INV.DEF.ACC'!I114)
C19: =IF('INV.DEF.ACC'!C93="","",'INV.DEF.ACC'!C93) | D19: =IF('INV.DEF.ACC'!F93="","",'INV.DEF.ACC'!F93) | E19: =IF('INV.DEF.ACC'!F115="","",'INV.DEF.ACC'!F115) | J19: =IF('INV.DEF.ACC'!H115="","",'INV.DEF.ACC'!H115) | L19: =IF('INV.DEF.ACC'!I115="","",'INV.DEF.ACC'!I115)
C21: =IF('INV.DEF.ACC'!C94="","",'INV.DEF.ACC'!C94) | D21: =IF('INV.DEF.ACC'!F94="","",'INV.DEF.ACC'!F94) | E21: =IF('INV.DEF.ACC'!F116="","",'INV.DEF.ACC'!F116) | J21: =IF('INV.DEF.ACC'!H116="","",'INV.DEF.ACC'!H116) | L21: =IF('INV.DEF.ACC'!I116="","",'INV.DEF.ACC'!I116)
C23: =IF('INV.DEF.ACC'!C95="","",'INV.DEF.ACC'!C95) | D23: =IF('INV.DEF.ACC'!F95="","",'INV.DEF.ACC'!F95) | E23: =IF('INV.DEF.ACC'!F117="","",'INV.DEF.ACC'!F117) | J23: =IF('INV.DEF.ACC'!H117="","",'INV.DEF.ACC'!H117) | L23: =IF('INV.DEF.ACC'!I117="","",'INV.DEF.ACC'!I117)
C24: Aprendizaje para otras faenas: | D24: =IF('INV.DEF.ACC'!K139="","",'INV.DEF.ACC'!K139)
B25: SEGURIDAD LABORAL.

Sheet Seguimiento Acc. CTP STP
D1: SEGUIMIENTO Y CONTROL DE INCIDENTE Y/O ACCIDENTES CTP/STP | S1: Código: | T1: RE-20-08
S2: Versión: | T2: 3
S3: Fecha: | T3: 46314
B5: N° | C5: NOMBRE ACCIDENTADO | D5: TIPO CONTRATO | E5: EVIDENCIA FOTOGRÁFICA | F5: FECHA | G5: DIAS PERDIDOS | H5: CLASIFICACIÓN (CTP/STP) Y POTENCIAL | I5: ACTIVIDAD QUE REALIZABA / LUGAR | J5: IDENTIFICACION DE GENERO | M5: JEFATURA RESPONSABLE | N5: MEDIDAS DE CONTROL | O5: RESPONSABLE DEL CUMPLIMIENTO | P5: FECHA COMPROMISO | Q5: EVIDENCIA MEJORA | R5: ESTADO DE LA MEDIDA (marque X) | U5: CAUSA RAÍZ (ID) | V5: TIPO DE CONTROL | W5: VERIFICADOR | X5: FECHA VERIFICACIÓN | Y5: RIESGO RESIDUAL
J6: M | K6: H | L6: OTROS | R6: IMPLEMENTADA | S6: VERIFICADA | T6: EFICAZ
B7: 1
B10: 2
B13: 3
B16: 4
B19: 5
B22: 6
B25: 7
B28: 8

Sheet Seguimiento Incidente daño 
D1: SEGUIMIENTO Y CONTROL DE INCIDENTE CON DAÑO MATERIAL Y/O AMBIENTAL | Q1: Código: | R1: RE-20-09
Q2: Versión: | R2: 3
Q3: Fecha: | R3: 46314
B5: N° | C5: DESCRIPCIÓN DEL INCIDENTE | D5: LUGAR DEL INCIDENTE | E5: EVIDENCIA FOTOGRAFICA | F5: FECHA | G5: NOMBRE OPERADOR O CONDUCTOR | H5: ACTIVIDAD QUE REALIZABA / LUGAR | I5: IDENTIFICACION DEL INCIDENTE | K5: JEFATURA RESPONSABLE | L5: MEDIDAS DE CONTROL | M5: RESPONSABLE DEL CUMPLIMIENTO | N5: FECHA COMPROMISO | O5: EVIDENCIA MEJORA | P5: ESTADO DE LA MEDIDA (marque X) | S5: CAUSA RAÍZ (ID) | T5: TIPO DE CONTROL | U5: VERIFICADOR | V5: FECHA VERIFICACIÓN | W5: RIESGO RESIDUAL
I6: MATERIAL | J6: AMBIENTAL | P6: IMPLEMENTADA | Q6: VERIFICADA | R6: EFICAZ
B7: 1
B10: 2
B13: 3
B16: 4
B19: 5
B22: 6
B25: 7
B28: 8

Sheet Reporte Cuasi Accidente
B1: REPORTE DE CUASI ACCIDENTE | D1: Código: | E1: RE-20-11
D2: Versión: | E2: 2
D3: Fecha: | E3: 46314
B4: CUASI-ACCIDENTE: Eventos no programados que bajo circunstancias ligeramente diferentes podrían haber ocasionado lesión a las personas, daño a los equipos, materiales y/o Medio Ambiente de la Planta u Oficina. No existe lesión ni daño a la propiedad
B5: SI EL EVENTO QUE ANALIZARA CONSIDERA LESIONES Y DAÑO A LA PROPIEDAD UTILICE FORMULARIO INVESTIGACION DE ACCIDENTES
B6: CENTRO DE TRABAJO: AREA:
B7: PERSONA QUIEN INFORMA EL CUASI ACCIDENTE:
B8: FECHA EN QUE SE INFORMA:
B9: FECHA EN QUE SUCEDIÓ EL CUASI ACCIDENTE: HORA :
B10: DESCRIBIR CLARAMENTE COMO SUCEDIÓ EL CUASI ACCIDENTE:
B16: ACCIONES TOMADAS PARA EVITAR SU OCURRENCIA
B23: POTENCIAL DEL EVENTO
B24: ¿SE INVESTIGA CON ÁRBOL DE CAUSAS? (obligatorio si el potencial es grave o fatal) | D24: =IF(D23="","",IF(D23="Grave o fatal","Sí, según DO-36","No obligatorio"))

Sheet Clasificación
C2: CATÁLOGO DE CLASIFICACIONES Y LISTAS DESPLEGABLES Investigación de accidentes e incidentes | G2: Código | H2: RE-20 Listas
G3: Versión | H3: 3
G4: Fecha | H4: 46314
B6: Cada columna es una lista desplegable de los formularios. Para agregar una opción, escríbela en la primera celda vacía de su columna y la lista se actualiza sola. No dejes celdas vacías entre opciones ni cambies los títulos de la fila 10.
B9: 1. EVENTO Y CLASIFICACIÓN | H9: 2. ACTIVIDAD, ACCIDENTE Y LESIÓN | P9: 3. CONDICIONES DEL LUGAR | U9: 4. ÁRBOL DE CAUSAS Y MEDIDAS | AE9: 5. INVESTIGACIÓN Y REGISTROS | AL9: 6. RESPUESTAS GENERALES | AR9: 7. ORGANIZACIÓN (completar) | AU9: 8. LISTAS ANTERIORES (modelo de causalidad de pérdidas; se conservan como referencia y no alimentan el árbol de causas)
B10: Tipo de evento | C10: Clasificación ante la mutualidad | D10: Potencial del evento | E10: Estatus ante la mutualidad | F10: Descripción | H10: Actividad que se realizaba (situación) | I10: Tipo de accidente | J10: Agente causante | K10: Categoría | L10: Fuente | M10: Zona corporal | N10: Daños o pérdidas | P10: Temperaturas | Q10: Clima | R10: Sistema de turnos | S10: Información del lugar físico | U10: ID de hechos | V10: Relación causal | W10: Tipo de control | X10: Correctiva / preventiva | Y10: Alcance | Z10: Prioridad | AA10: Estado de la medida | AB10: Resultado de eficacia | AC10: Riesgo residual | AE10: Tipo de evidencia | AF10: Calidad de quien declara | AG10: Rol en la investigación | AH10: Resultado de calidad | AI10: Resultado de la revisión | AJ10: Decisión del Comité Paritario | AL10: Sí / No | AM10: Sí / No / No verificable | AN10: Sí / No / No aplica | AO10: Autorización o licencia | AP10: Sexo (registro estadístico) | AR10: Subgerencias | AS10: Zonas / talleres | AU10: Acto subestándar | AV10: Condición subestándar | AW10: Factor personal | AX10: Factor del trabajo | AY10: Causa raíz (modelo anterior) | AZ10: Probabilidad | BA10: Severidad | BB10: Estado civil | BC10: Tipo (anterior)
B11: Se usa en: RE-20-02, RE-20-04 | C11: Se usa en: Seguimiento y estadística | D11: Se usa en: RE-20-02, RE-20-04, RE-20-11 | E11: Se usa en: Seguimiento RE-20-08 | F11: Referencia | H11: Se usa en: RE-20-04 | I11: Se usa en: RE-20-04 | J11: Se usa en: RE-20-04 | K11: Referencia | L11: Se usa en: RE-20-04 | M11: Se usa en: RE-20-02, RE-20-04 | N11: Se usa en: Estadística | P11: Se usa en: RE-20-02 | Q11: Se usa en: RE-20-02 | R11: Se usa en: RE-20-02 | S11: Se usa en: RE-20-02 | U11: Se usa en: RE-20-04, RE-20-05 | V11: Se usa en: RE-20-05 | W11: Se usa en: RE-20-04, RE-20-08, RE-20-09 | X11: Se usa en: RE-20-04 | Y11: Se usa en: RE-20-04 | Z11: Se usa en: RE-20-04 | AA11: Se usa en: RE-20-04 | AB11: Se usa en: RE-20-04 | AC11: Se usa en: RE-20-04, RE-20-08, RE-20-09 | AE11: Se usa en: RE-20-04 | AF11: Se usa en: RE-20-04, RE-20-07 | AG11: Se usa en: RE-20-04 | AH11: Se usa en: RE-20-13 | AI11: Se usa en: RE-20-13 | AJ11: Se usa en: RE-20-04 | AL11: Se usa en: Varias hojas | AM11: Se usa en: RE-20-04 | AN11: Se usa en: RE-20-04 | AO11: Se usa en: RE-20-04 | AP11: Se usa en: RE-20-04, DIAT | AR11: Se usa en: Por completar | AS11: Se usa en: Por completar | AU11: Se usa en: Sin uso | AV11: Se usa en: Sin uso | AW11: Se usa en: Sin uso | AX11: Se usa en: Sin uso | AY11: Se usa en: Sin uso | AZ11: Se usa en: Sin uso | BA11: Se usa en: Sin uso | BB11: Se usa en: Sin uso | BC11: Se usa en: Sin uso
B12: Accidente del trabajo CTP | C12: Accidente Laboral | D12: Bajo | E12: Abierto | F12: Refiere a Accidentes aceptados por la mutual pero que no tienen fecha de alta definida | H12: Conducción de camión ampliroll | I12: Aplastamiento por carga, equipo o contenedor | J12: Advertencias poco claras o inexistentes (auditivas o visuales) | K12: Equipos | L12: Camión ampliroll | M12: Brazos (y/u hombros) | N12: Contusiones | P12: Altas temperaturas | Q12: Lluvia | R12: Día | S12: Iluminación deficiente | U12: H1 | V12: Cadena | W12: Eliminación | X12: Correctiva | Y12: Local | Z12: Alta | AA12: Pendiente | AB12: Eficaz | AC12: Bajo | AE12: Fotografía o video | AF12: Involucrado | AG12: Responsable de la investigación | AH12: Cumple | AI12: Aprobado | AJ12: No se determina negligencia inexcusable | AL12: Sí | AM12: Sí | AN12: Sí | AO12: Vigente | AP12: Hombre | AU12: Conducir, operar sin autoriz. | AV12: Falta dispos. de seg. o protec. | AW12: Falta de conoc. o cap. | AX12: Proced. de operac. incorrecto | AY12: Falta de Procedimientos | AZ12: Muy improbable 1 | BA12: Insignificante 1 | BB12: Casado/a | BC12: Accidente
B13: Accidente del trabajo STP | C13: Enfermedad Profesional | D13: Medio | E13: Cerrado | F13: Refiere a Accidentes aceptados por la mutual con fecha de alta definida | H13: Carga, descarga y enganche de contenedores con camión ampliroll | I13: Atrapamiento entre objetos en movimiento o fijo y movimiento | J13: Conductores eléctricos sin protección o falta de aislación | K13: Equipos | L13: Camión tolva | M13: Brazos y Piernas | N13: Lesión musculoesquelética | P13: Bajas temperaturas | Q13: Granizo | R13: Tarde | S13: Plataformas de trabajo inadecuadas o fuera de estándar | U13: H2 | V13: Conjunción | W13: Ingeniería | X13: Preventiva | Y13: Global | Z13: Media | AA13: Implementada | AB13: Parcial | AC13: Medio | AE13: Croquis o medición | AF13: Testigo | AG13: Prevención de Riesgos | AH13: Parcial | AI13: Aprobado con observaciones | AJ13: Se determina negligencia inexcusable | AL13: No | AM13: No | AN13: No | AO13: No vigente | AP13: Mujer | AU13: Dejar de asegurar cont. mov. | AV13: Falta sistema de advertencia | AW13: No conoce el riesgo | AX13: Diseño inadecuado y peligroso | AY13: Falta de Políticas | AZ13: Improbable 2 | BA13: Bajo 4 | BB13: Soltero/a | BC13: Enfermedad profesional
B14: Accidente grave | C14: Reingreso AL | D14: Alto | E14: En Investigación | F14: Refiere a Accidentes en proceso de evaluación por la mutual. | H14: Conducción de camión tolva | I14: Atrapamiento por objeto fijo o en movimiento | J14: Equipo con partes alteradas o defectuosas | K14: Equipos | L14: Camión pluma | M14: Cabeza | N14: Daño ocular | P14: No aplica | Q14: Nieve | R14: Noche | S14: Escaleras inadecuadas o fuera de estándar | U14: H3 | V14: Independiente | W14: Administrativa | Z14: Baja | AA14: Verificada | AB14: No eficaz | AC14: Alto | AE14: Declaración | AF14: Persona accidentada | AG14: Jefatura o supervisión | AH14: No cumple | AI14: Requiere corrección | AJ14: No aplica | AM14: No verificable | AN14: No aplica | AO14: No aplica | AU14: Conducir a veloc. anormal | AV14: Propenso a arder o explotar | AW14: No conoce la forma segura | AX14: Construcción, instalación defectuosa | AY14: Procesos mal establecidos | AZ14: Remoto 3 | BA14: Moderado 9 | BB14: Separado/a
B15: Accidente fatal | C15: Reingreso EP | D15: Grave o fatal | E15: Rechazado | F15: Refiere a Accidentes rechazados como accidentes laboral por la mutual | H15: Carga y descarga de camión tolva (volteo) | I15: Atropello | J15: Equipos sin mantención o revisión de funcionamiento | K15: Equipos | L15: Grúa pluma 25 t | M15: Lumbar | N15: Daño en la piel | Q15: Tormenta | R15: No aplica | S15: No aplica | U15: H4 | W15: EPP | AA15: Eficaz | AE15: Procedimiento de trabajo | AG15: Representante Comité Paritario | AU15: Dejar de advertir | AV15: Susceptible mov. inesperado | AW15: Tiene poca pericia | AX15: Sist. de mantención incorrecto | AY15: Actividades no incluida en procesos | AZ15: Ocasional 4 | BA15: Significativo 16 | BB15: Viudo/a
B16: Accidente de trayecto | C16: Trayecto | E16: Revizar | F16: Refiere a Accidentes de los que no se tiene información legal aún. | H16: Transporte de materiales peligrosos | I16: Caída a diferente nivel | J16: Falla en el sistema de aislación | K16: Equipos | L16: Grúa pluma 100 t | M16: Manos (y/o dedos) | N16: Cortes | Q16: Tormenta eléctrica | U16: H5 | AA16: No eficaz | AE16: Matriz IPER | AG16: Delegado de prevención | AU16: Remover sist. de seguridad | AV16: Orden, aseo, almacen. inadec. | AW16: Formación insuficiente | AX16: Desgaste excesivo por sobre la capacidad nominal | AY16: No realizar controles | AZ16: Frecuente 5 | BA16: Catastrófico 25
B17: Enfermedad profesional | H17: Transporte de materiales no peligrosos | I17: Caída al mismo nivel | J17: Falta de manual de instrucciones (original) | K17: Equipos | L17: Grúa horquilla | M17: Más de una zona | N17: Heridas corto punzantes | Q17: Nublado | U17: H6 | AE17: Registro de capacitación | AG17: Trabajador conocedor de la tarea | AU17: Usar elementos defectuosos | AV17: Superficies de trab. riesgosas | AW17: Motiv. Incorr. | AX17: Desgaste por uso normal
B18: Incidente peligroso | H18: Retiro, transporte y disposición de lodos sanitarios | I18: Caída de carga suspendida | J18: Inexistencia de manuales de operación | K18: Equipos | L18: Alzahombre | M18: Ojos | N18: Daño a vehículo o equipo móvil | Q18: Soleado | U18: H7 | AE18: ODI | AG18: Representante sindical | AU18: Usar de manera incorrecta | AV18: Cond. Ambientales adversas | AW18: Trato de ganar tiempo | AX18: Expuesto a corrosión
B19: Cuasi accidente | H19: Izaje con camión pluma | I19: Caída desde plataforma de alzahombre o equipo | J19: Protección de maquinaria inexistente o insuficiente | K19: Equipos | L19: Maquinaria pesada | M19: Otros | N19: Daño en infraestructura | Q19: No aplica | U19: H8 | AE19: Mantención o inspección | AG19: Empresa principal | AU19: Asumir posición incorrecta | AV19: Defectos en equipos, herramientas e instalaciones | AW19: Evita esfuerzo | AX19: Uso anormal, abuso o mal empleo por el usuario
B20: Daño material | H20: Izaje con grúa pluma 25 t | I20: Choque contra elementos móviles | J20: Sistemas de bloqueo inexistentes o desconectados | K20: Equipos | L20: Vehículo liviano | M20: Piernas | N20: Daño a equipos o herramientas | U20: H9 | AE20: Permiso de trabajo o AST | AG20: Contratista | AU20: Reparar equipo en movimiento | AV20: Iluminación defectuosa | AW20: Desea aprobación del grupo | AX20: Adquisición mal estandarizada
B21: Daño ambiental | H21: Izaje con grúa pluma 100 t | I21: Choque contra objetos o estructura fija | J21: Estrobos, eslingas o accesorios de izaje defectuosos | K21: Equipos | L21: Equipos y herramientas de taller | M21: Pies | N21: Daño a terceros | U21: H10 | AE21: Registro de jornada | AG21: Otro | AU21: Ocuparse de juegos | AV21: Equipo de protección inadec. | AW21: No planea el trabajo | AX21: Sin inspección previa
H22: Estrobado, rigger y señalero en maniobras de izaje | I22: Choque por otro vehículo | J22: Capacidad de la grúa excedida o sin tabla de carga | K22: Equipos | L22: Materiales peligrosos | M22: Tronco | U22: H11 | AE22: Especificación de equipo o EPP | AU22: Beber o consumir drogas | AV22: Otros factores (Indique) | AW22: Problemas físicos/emocional | AX22: Acciones ajenas a la empresa
H23: Operación de maquinaria pesada | I23: Colisión entre vehículos o maquinaria | J23: Contenedor o tolva sin traba o seguro | K23: Equipos | L23: Materiales no peligrosos | U23: H12 | AE23: Alarma o telemetría | AU23: Violar reglas de seguridad | AW23: Estado emocional | AX23: Causas naturales
H24: Operación de grúa horquilla | I24: Contacto con electricidad | J24: Visibilidad reducida o punto ciego del equipo | K24: Equipos | L24: Lodos sanitarios | U24: H13 | AE24: Registro de supervisión | AU24: Actos incorrectos de otros | AW24: Estaba fatigado | AX24: Desviarse del procedimiento
H25: Trabajo en altura con alzahombre | I25: Contacto con fuego | J25: Plataforma o canastillo de alzahombre sin inspección | K25: Equipos | L25: Equipos | U25: H14 | AE25: Otro | AU25: Otros (Indique) | AW25: Estaba enfermo | AX25: Otros (Indique)
H26: Mantención de maquinaria pesada en taller | I26: Contacto con objetos calientes | J26: Almacenamiento incorrecto | K26: Materiales | L26: Materiales | U26: H15 | AW26: Impedimento físico
H27: Mantención de camiones y equipos de transporte en taller | I27: Contacto con objetos cortantes | J27: Envase dañado o con defectos | K27: Materiales | L27: Herramientas | U27: H16 | AW27: Estrés incontrolado
H28: Mantención de equipos en terreno | I28: Contacto con objetos punzantes | J28: Falta de hoja de datos de seguridad | K28: Materiales | L28: Ambiente | U28: H17 | AW28: Estaba en tratamiento medico
H29: Soldadura y oxicorte | I29: Contacto con sustancias químicas | J29: Falta de rotulación | K29: Materiales | L29: Ambiente higiénico | U29: H18 | AW29: Expuesto a trabajo monótono
H30: Lavado de camiones y equipos | I30: Contacto de pluma o equipo con línea eléctrica | J30: Productos incompatibles o reactivos | K30: Materiales | L30: Otros | U30: H19
H31: Administrativas de oficina | I31: Derrame o fuga de sustancia peligrosa | J31: Carga mal estibada o sin amarre | K31: Materiales | U31: H20
H32: Administrativas de terreno | I32: Explosión | J32: Carga de combustible | K32: Ambiente
H33: Conducción de vehículos | I33: Golpeado con objeto o herramienta | J33: Espacio confinado | K33: Ambiente
H34: Excavaciones | I34: Golpeado contra objetos o equipos | J34: Espacio reducido | K34: Ambiente
H35: Izamiento de cargas u operaciones de levante (tecles, grúas torre, etc.) | I35: Golpeado por objeto | J35: Falta de delimitación de pisos | K35: Ambiente
H36: Labores de vigilancia y protección industrial | I36: Incendio | J36: Falta de orden y aseo | K36: Ambiente
H37: Labores en espacios confinados | I37: Inmersión | J37: Falta de señalización | K37: Ambiente
H38: Manejo de objetos calientes o fundidos | I38: Intoxicación por alimentos | J38: Iluminación insuficiente | K38: Ambiente
H39: Manejo de animales | I39: Picadura o mordedura de animal o insecto | J39: Piso fuera de norma o especificaciones | K39: Ambiente
H40: Manejo de cortopunzantes con material biológico | I40: Volcamiento de vehículo o maquinaria | J40: Presencia de gases o agentes peligrosos | K40: Ambiente
H41: Manejo manual de cargas | I41: Exposición a agentes biológicos (virus, bacterias, hongos, etc.) | J41: Superficies calientes | K41: Ambiente
H42: Manipulación de herramientas manuales | I42: Exposición a lodos sanitarios (agente biológico) | J42: Estabilizadores sobre terreno inestable o sin placas de apoyo | K42: Ambiente
H43: Operación de equipos o herramientas con partes en movimiento | I43: Exposición a calor | J43: Línea eléctrica cercana a la zona de trabajo | K43: Ambiente
... H51: Otros | I51: Exposición a radiación ionizante (rayos X, alfa, beta, gamma) | J51: Gases (agente químico) | K51: Ambiente higiénico
...
